Workbook

Sheet P&L 2022-2024
B2: VioTrans Group SRL | C2: Source: https://www.ecb.europa.eu/stats/policy_and_exchange_rates/euro_reference_exchange_rates/html/eurofxref-graph-ron.de.html
C3: EUR vs. RON | E3: EUR vs. RON | G3: EUR vs. RON
B4: In € | C4: 46021 | E4: 45655 | G4: 45657
C5: 4.949 | E5: 4.975 | G5: 4.974
B7: No. Description | C7: for the period ended December 31, 2022 | E7: for the period ended December 31, 2023 | G7: for the period ended December 31, 2024
B8: 1. Net turnover (row 03 + 04 - 05 + 06) | C8: 38216486 | D8: =C8/C24 -> 0.9884008 | E8: 37396294 | F8: =E8/E24 -> 0.98546718 | G8: 34006909 | H8: =G8/G24 -> 0.98263516
B9: - out of which net turnover for the main activity | C9: 0 | E9: 0 | G9: 32096156
B10: - out of which, the net turnover achieved from operations carried out on national territory | C10: 0 | E10: 0 | G10: 341506.25
B11: Sales of goods (acc. 701 + 702 + 703 + 704 + 705 + 706 + 708) | C11: 36069540 | D11: =C11/C24 -> 0.93287391 | E11: 0 | F11: =E11/E24 -> 0 | G11: 32197889 | H11: =G11/G24 -> 0.93036324
B12: Sales of merchandise (acc. 707) | C12: 2146945.6 | D12: =C12/C24 -> 0.055526895 | E12: 0 | F12: =E12/E24 -> 0 | G12: 1809019.5 | H12: =G12/G24 -> 0.052271913
B13: Discounts granted (acc. 709) | C13: 0 | E13: 0 | G13: 0
B14: Revenue from operating subsidies related to the turnover (acc. 7411) | C14: 0 | E14: 0 | G14: 0
B15: 2. Revenue related to the cost of the work in progress (acc. 711+712) - Cr Balance | C15: 0 | E15: 0 | G15: 0
B16: Revenue related to the cost of the work in progress (acc. 711 + 712) - Dr Balance | C16: 0 | E16: 0 | G16: 0
B17: 3. Income from production of tangible and intangible assets (acc. 721 + 722) | C17: 0 | E17: 0 | G17: 0
B18: 4. Income from the revaluation of tangible assets (acc. 755) | C18: 0 | E18: 0 | G18: 0
B19: 5. Income from production of real estate investments (acc. 725) | C19: 0 | E19: 0 | G19: 0
B20: 6. Income from operating subsidies (acc. 7412 + 7413 + 7414 + 7415 + 7416 + 7417 + 7419) | C20: 0 | E20: 0 | G20: 0
B21: 7. Other operating income (acc. 751 + 758 + 7815) | C21: 448482.52 | D21: =C21/C24 -> 0.011599195 | E21: 551488.24 | F21: =E21/E24 -> 0.014532819 | G21: 600960.19 | H21: =G21/G24 -> 0.017364843
B22: - out of which, income from investment subsidies (acc. 7584) | C22: 6159.6282 | D22: =C22/C24 -> 0.00015930773 | E22: 0 | G22: 0
B23: - out of which, income from negative goodwill (acc. 7815) | C23: 0 | E23: 0 | G23: 0
B24: OPERATING INCOME – TOTAL (rows 01 + 07 – 08 + 09 + 10 + 11 + 12 + 13) | C24: 38664968 | D24: =SUM(D11:D23) -> 1.0001593 | E24: 37947783 | F24: =SUM(F11:F23) -> 0.014532819 | G24: 34607869 | H24: =SUM(H11:H23) -> 1
B25: Growth in % | E25: =E24/C24-1 -> -0.018548728 | G25: =G24/E24-1 -> -0.088013411
B26: 8. a) Expenses related to raw materials and consumables (acc. 601 + 602) | C26: 6764286.9 | D26: =C$26/$C$24 -> 0.17494614 | E26: 6514435.2 | F26: =E$26/$E$24 -> 0.1716684 | G26: 5768370.5 | H26: =G$26/$G$24 -> 0.16667801
B27: Other material expenses (acc. 603 + 604 + 606 + 608) | C27: 30171.752 | D27: =$C27/$C$24 -> 0.0007803382 | E27: 33208.442 | F27: =$E27/$E$24 -> 0.0008751089 | G27: 21910.334 | H27: =$G27/$G$24 -> 0.00063310266
B28: b) Other external expenses (power and water supply) (acc. 605) | C28: 86376.44 | D28: =$C28/$C$24 -> 0.0022339716 | E28: 61133.065 | F28: =$E28/$E$24 -> 0.0016109786 | G28: 40715.32 | H28: =$G28/$G$24 -> 0.0011764758
B29: - out of which, expenses with power consumption (acc. 6051) | C29: 84990.099 | D29: =$C29/$C$24 -> 0.0021981163 | E29: 58890.452 | F29: =$E29/$E$24 -> 0.0015518813 | G29: 37208.484 | H29: =$G29/$G$24 -> 0.0010751452
B30: - out of which, expenses with natural gas consumption (acc. 6053) | C30: 0 | E30: 0 | G30: 0
B31: c) Merchandise expenses (acc. 607) | C31: 2145422.1 | D31: =$C31/$C$24 -> 0.055487491 | E31: 1748810.5 | F31: =$E31/$E$24 -> 0.046084655 | G31: 1808855.6 | H31: =$G31/$G$24 -> 0.052267178
B32: Commercial discounts received (acc. 609) | C32: 0 | E32: 0 | G32: 0
B33: 9. Personnel expenses (rows 25 + 26), out of which: | C33: 3420668.4 | D33: =$C33/$C$24 -> 0.088469448 | E33: 4168543.1 | F33: =$E33/$E$24 -> 0.10984945 | G33: 4283540.6 | H33: =$G33/$G$24 -> 0.1237736
B34: a) Salaries and allowance (acc. 641 + 642 + 643 + 644) | C34: 3347551.6 | D34: =$C34/$C$24 -> 0.086578413 | E34: 4079188.7 | F34: =$E34/$E$24 -> 0.10749479 | G34: 4188603.7 | H34: =$G34/$G$24 -> 0.12103039
B35: b) Social security (acc. 645 + 646) | C35: 73116.791 | D35: =$C35/$C$24 -> 0.0018910346 | E35: 89354.372 | F35: =$E35/$E$24 -> 0.0023546665 | G35: 94936.872 | H35: =$G35/$G$24 -> 0.0027432164
B36: 10. a) Value adjustments regarding tangible and intangible assets (rows 28+29-30) | C36: 2860043.2 | D36: =$C36/$C$24 -> 0.073969884 | E36: 2910385.1 | F36: =$E36/$E$24 -> 0.076694472 | G36: 2502104.1 | H36: =$G36/$G$24 -> 0.072298706
B37: a. 1) Expenses with depreciation and amortisation (acc. 6811) | C37: 2860043.2 | D37: =$C37/$C$24 -> 0.073969884 | E37: 2910385.1 | F37: =$E37/$E$24 -> 0.076694472 | G37: 2502104.1 | H37: =$G37/$G$24 -> 0.072298706
B38: a. 2) Other expenses (acc. 6813 + 6817+ from acc. 6818) | C38: 0 | E38: 0 | G38: 0
B39: a. 3) Income (acc. 7813 + from acc. 7818) | C39: 0 | E39: 0 | G39: 0
B40: 10. b) Value adjustments regarding current assets (rows 31 – 32) | C40: 1497.2722 | D40: =$C40/$C$24 -> 3.8724257e-05 | E40: -6619.2965 | F40: =$E40/$E$24 -> -0.00017443171 | G40: 36502.01 | H40: =$G40/$G$24 -> 0.0010547315
B41: b. 1) Expenses (acc. 654 + 6814 + from acc. 6818) | C41: 60289.351 | D41: =$C41/$C$24 -> 0.0015592758 | E41: 8057.2864 | F41: =$E41/$E$24 -> 0.00021232562 | G41: 48636.711 | H41: =$G41/$G$24 -> 0.0014053657
B42: b. 2) Income (acc. 754 + 7814 + from acc. 7818) | C42: 58792.079 | D42: =$C42/$C$24 -> 0.0015205516 | E42: 14676.583 | F42: =$E42/$E$24 -> 0.00038675733 | G42: 12134.7 | H42: =$G42/$G$24 -> 0.00035063414
...

Sheet Balance Sheet 2022-2024
B2: VioTrans Group SRL | C2: Source: https://www.ecb.europa.eu/stats/policy_and_exchange_rates/euro_reference_exchange_rates/html/eurofxref-graph-ron.de.html
C3: EUR vs. RON | E3: EUR vs. RON | G3: EUR vs. RON
B4: In € | C4: 46021 | E4: 45655 | G4: 45657
C5: 4.949 | E5: 4.975 | G5: 4.974
B7: No. Description | C7: as at December 31, 2022 | E7: as at December 31, 2023 | G7: as at December 31, 2024
B8: NON-CURRENT ASSETS
B9: I. INTANGIBLE ASSETS
B10: 1 Set-up expenses (acc. 201 - 2801) | C10: 0 | E10: 0 | G10: 0
B11: 2 Development expenses (acc. 2023 - 2803 - 2903) | C11: 0 | E11: 0 | G11: 0
B12: 3 Concessions, patents, licenses, trademarks, similar rights and assets and other intangible assets (acc. 205 + 208 - 2805 - 2808 - 2905 - 2908) | C12: 4011.3154 | D12: =C12/C37 -> 0.00041856634 | E12: 25585.528 | F12: =E12/E37 -> 0.0034451766 | G12: 19983.514 | H12: =G12/G37 -> 0.0038357813
B13: 4 Goodwill (acc. 2071 - 2807) | C13: 0 | E13: 0 | G13: 0
B14: 5 Intangible exploration assets and evaluation of mineral resources (206 - 2806 - 2906) | C14: 0 | E14: 0 | G14: 0
B15: 6 Advances (acc. 4094 - 4904) | C15: 0 | E15: 0 | G15: 0
B16: TOTAL (row 01 to 06) | C16: 4011.3154 | D16: =C16/C66 -> 0.00019013009 | E16: 25585.528 | F16: =E16/E66 -> 0.0013602633 | G16: 19983.514 | H16: =G16/G66 -> 0.0012980413
B17: II. TANGIBLE ASSETS | C17: 0 | E17: 0 | G17: 0
B18: 1 Land and buildings (acc. 211 + 212 - 2811 - 2812 - 2911 - 2912) | C18: 1523198.8 | D18: =$C18/$C$66 -> 0.072197246 | E18: 1452865.5 | F18: =$E18/$E$66 -> 0.077242091 | G18: 1370667.7 | H18: =$G18/$G$66 -> 0.08903255
B19: 2 Installations and machinery (acc. 213 + 223 - 2813 - 2913) | C19: 7850724.8 | D19: =$C19/$C$66 -> 0.37211209 | E19: 5860386.3 | F19: =$E19/$E$66 -> 0.31156944 | G19: 3554068 | H19: =$G19/$G$66 -> 0.23085664
B20: 3 Other installations, machines and furniture (acc. 214 + 224 - 2814 - 2914) | C20: 76867.448 | D20: =$C20/$C$66 -> 0.003643397 | E20: 77261.709 | F20: =$E20/$E$66 -> 0.0041076451 | G20: 154964.82 | H20: =$G20/$G$66 -> 0.010065834
B21: 4 Investment property (acc. 215 - 2815 - 2915) | C21: 0 | E21: 0 | G21: 0
B22: 5 Tangible assets in progress (acc. 231 - 2931) | C22: 4992.5237 | D22: =$C22/$C$66 -> 0.00023663783 | E22: 0 | G22: 0
B23: 6 Investment property in progress (acc. 235 - 2935) | C23: 0 | E23: 0 | G23: 0
B24: 7 Tangible assets for exploration and valuation of mineral resources (acc. 216 - 2816 - 2916) | C24: 0 | E24: 0 | G24: 0
B25: 8 Productive biological assets (acc. 217 + 227 - 2817 - 2917) | C25: 0 | E25: 0 | G25: 0
B26: 9 Advances (acc. 4093 - 4903) | C26: 120859.57 | D26: =$C26/$C$66 -> 0.0057285547 | E26: 0 | G26: 100002.01 | H26: =$G26/$G$66 -> 0.0064956913
B27: TOTAL (row 08 to 16) | C27: 9576643.2 | D27: =$C27/$C$66 -> 0.45391793 | E27: 7390513.6 | F27: =$E27/$E$66 -> 0.39291917 | G27: 5179702.5 | H27: =$G27/$G$66 -> 0.33645071
B28: III. FINANCIAL ASSETS | C28: 0 | E28: 0 | G28: 0
B29: 1 Investments in related parties (acc. 261 - 2961) | C29: 0 | E29: 0 | G29: 0
B30: 2 Loans granted to related parties (acc. 2671 + 2671 - 2964) | C30: 0 | E30: 0 | G30: 0
B31: 3 Equity investment (acc. 262 + 263 - 2962) | C31: 0 | E31: 0 | G31: 0
B32: 4 Loans granted to associated entities and jointly controlled entities (acc. 2673 + 2674 - 2965) | C32: 0 | E32: 0 | G32: 0
B33: 5 Other fixed assets (acc. 265 + 266 - 2963) | C33: 0 | E33: 0 | G33: 0
B34: 6 Other loans (acc. 2675* + 2676* + 2677 + 2678* + 2679* - 2966* - 2968*) | C34: 2809.4565 | D34: =$C34/$C$66 -> 0.00013316385 | E34: 10378.693 | F34: =$E34/$E$66 -> 0.00055178678 | G34: 10077.805 | H34: =$G34/$G$66 -> 0.00065460991
B35: TOTAL (row 18 to 23) | C35: 2809.4565 | D35: =$C35/$C$66 -> 0.00013316385 | E35: 10378.693 | F35: =$E35/$E$66 -> 0.00055178678 | G35: 10077.805 | H35: =$G35/$G$66 -> 0.00065460991
B37: TOTAL NON-CURRENT ASSETS (row 07+17+24) | C37: 9583463.9 | D37: =$C37/$C$66 -> 0.45424122 | E37: 7426477.8 | F37: =$E37/$E$66 -> 0.39483122 | G37: 5209763.8 | H37: =$G37/$G$66 -> 0.33840337
B39: CURRENT ASSETS | C39: 0 | E39: 0 | G39: 0
B40: I. INVENTORIES | C40: 0 | E40: 0 | G40: 0
B41: 1 Raw materials and consumables (acc. 301 + 302 + 303 +/- 308 +321 + 322 + 323 + 328 + 351 + 358 + 381 +/- 388 - 391 - 392 - 3951 - 3958 - 398) | C41: 144370.78 | D41: =$C41/$C$66 -> 0.0068429496 | E41: 133187.54 | F41: =$E41/$E$66 -> 0.0070809609 | G41: 141271.21 | H41: =$G41/$G$66 -> 0.0091763572
B42: 2 Production in progress (acc. 331 + 332 +341 +/- 348* - 393 - 3941 - 3952) | C42: 0 | E42: 0 | G42: 0
B43: 3 Finished goods and commodities (acc. 327 + 345 + 346 + 347 +/- 348* + 354 + 356 + 357 + 361 + 326 +/- 368 + 371 +/- 378 - 3945 - 3946 - 3947 - 3953 - 3954 - 3955 - 3956 - 3957 - 396 - 397 - din ct 4428) | C43: 0 | E43: 0 | G43: 0
B44: 4 Advances (acc. 4091 - 4901) | C44: 0 | E44: 0 | G44: 0
...

Sheet P&L 2022-2024 (2)
B2: VioTrans Group SRL | C2: Source: https://www.ecb.europa.eu/stats/policy_and_exchange_rates/euro_reference_exchange_rates/html/eurofxref-graph-ron.de.html
C3: EUR vs. RON | E3: EUR vs. RON | G3: EUR vs. RON
B4: In € | C4: 46021 | E4: 45655 | G4: 45657
C5: 4.949 | E5: 4.975 | G5: 4.974
B7: No. Description | C7: for the period ended December 31, 2022 | E7: for the period ended December 31, 2023 | G7: for the period ended December 31, 2024
B8: 1. Net turnover | C8: =SUM(C11:C14) -> 38216486 | D8: =C8/C24 -> 0.9884008 | E8: 37396294 | F8: =E8/E24 -> 0.98546718 | G8: =SUM(G11:G14) -> 34006909 | H8: =G8/G24 -> 0.98263516
B9: - out of which net turnover for the main activity | C9: 0 | E9: 0 | G9: 32096156
B10: - out of which, the net turnover achieved from operations carried out on national territory | C10: 0 | E10: 0 | G10: 341506.25
B11: Sales of goods | C11: 36069540 | D11: =C11/C24 -> 0.93287391 | E11: 0 | F11: =E11/E24 -> 0 | G11: 32197889 | H11: =G11/G24 -> 0.93036324
B12: Sales of merchandise | C12: 2146945.6 | D12: =C12/C24 -> 0.055526895 | E12: 0 | F12: =E12/E24 -> 0 | G12: 1809019.5 | H12: =G12/G24 -> 0.052271913
B13: Discounts granted | C13: 0 | E13: 0 | G13: 0
B14: Revenue from operating subsidies related to the turnover | C14: 0 | E14: 0 | G14: 0
B15: 2. Revenue related to the cost of the work in progress | C15: 0 | E15: 0 | G15: 0
B16: Revenue related to the cost of the work in progress | C16: 0 | E16: 0 | G16: 0
B17: 3. Income from production of tangible and intangible assets | C17: 0 | E17: 0 | G17: 0
B18: 4. Income from the revaluation of tangible assets | C18: 0 | E18: 0 | G18: 0
B19: 5. Income from production of real estate investments | C19: 0 | E19: 0 | G19: 0
B20: 6. Income from operating subsidies | C20: 0 | E20: 0 | G20: 0
B21: 7. Other operating income | C21: 448482.52 | D21: =C21/C24 -> 0.011599195 | E21: 551488.24 | F21: =E21/E24 -> 0.014532819 | G21: 600960.19 | H21: =G21/G24 -> 0.017364843
B22: - out of which, income from investment subsidies | C22: 6159.6282 | D22: =C22/C24 -> 0.00015930773 | E22: 0 | G22: 0
B23: - out of which, income from negative goodwill | C23: 0 | E23: 0 | G23: 0
B24: OPERATING INCOME – TOTAL | C24: =SUM(C21,C8) -> 38664968 | D24: =SUM(D11:D23) -> 1.0001593 | E24: =SUM(E21,E8) -> 37947783 | F24: =SUM(F11:F23) -> 0.014532819 | G24: =SUM(G21,G8) -> 34607869 | H24: =SUM(H11:H23) -> 1
B25: Growth in % | E25: =E24/C24-1 -> -0.018548728 | G25: =G24/E24-1 -> -0.088013411
B26: 8. a) Expenses related to raw materials and consumables | C26: 6764286.9 | D26: =C$26/$C$24 -> 0.17494614 | E26: 6514435.2 | F26: =E$26/$E$24 -> 0.1716684 | G26: 5768370.5 | H26: =G$26/$G$24 -> 0.16667801
B27: Other material expenses | C27: 30171.752 | D27: =$C27/$C$24 -> 0.0007803382 | E27: 33208.442 | F27: =$E27/$E$24 -> 0.0008751089 | G27: 21910.334 | H27: =$G27/$G$24 -> 0.00063310266
B28: b) Other external expenses (power and water supply) | C28: 86376.44 | D28: =$C28/$C$24 -> 0.0022339716 | E28: 61133.065 | F28: =$E28/$E$24 -> 0.0016109786 | G28: 40715.32 | H28: =$G28/$G$24 -> 0.0011764758
B29: - out of which, expenses with power consumption | C29: 84990.099 | D29: =$C29/$C$24 -> 0.0021981163 | E29: 58890.452 | F29: =$E29/$E$24 -> 0.0015518813 | G29: 37208.484 | H29: =$G29/$G$24 -> 0.0010751452
B30: - out of which, expenses with natural gas consumption | C30: 0 | E30: 0 | G30: 0
B31: c) Merchandise expenses | C31: 2145422.1 | D31: =$C31/$C$24 -> 0.055487491 | E31: 1748810.5 | F31: =$E31/$E$24 -> 0.046084655 | G31: 1808855.6 | H31: =$G31/$G$24 -> 0.052267178
B32: Commercial discounts received | C32: 0 | E32: 0 | G32: 0
B33: 9. Personnel expenses | C33: =SUM(C34:C35) -> 3420668.4 | D33: =$C33/$C$24 -> 0.088469448 | E33: =SUM(E34:E35) -> 4168543.1 | F33: =$E33/$E$24 -> 0.10984945 | G33: =SUM(G34:G35) -> 4283540.6 | H33: =$G33/$G$24 -> 0.1237736
B34: a) Salaries and allowance | C34: 3347551.6 | D34: =$C34/$C$24 -> 0.086578413 | E34: 4079188.7 | F34: =$E34/$E$24 -> 0.10749479 | G34: 4188603.7 | H34: =$G34/$G$24 -> 0.12103039
B35: b) Social security | C35: 73116.791 | D35: =$C35/$C$24 -> 0.0018910346 | E35: 89354.372 | F35: =$E35/$E$24 -> 0.0023546665 | G35: 94936.872 | H35: =$G35/$G$24 -> 0.0027432164
B36: 10. a) Value adjustments regarding tangible and intangible assets | C36: =SUM(C37:C39) -> 2860043.2 | D36: =$C36/$C$24 -> 0.073969884 | E36: =SUM(E37:E39) -> 2910385.1 | F36: =$E36/$E$24 -> 0.076694472 | G36: =SUM(G37:G39) -> 2502104.1 | H36: =$G36/$G$24 -> 0.072298706
B37: a. 1) Expenses with depreciation and amortisation | C37: 2860043.2 | D37: =$C37/$C$24 -> 0.073969884 | E37: 2910385.1 | F37: =$E37/$E$24 -> 0.076694472 | G37: 2502104.1 | H37: =$G37/$G$24 -> 0.072298706
B38: a. 2) Other expenses | C38: 0 | E38: 0 | G38: 0
B39: a. 3) Income | C39: 0 | E39: 0 | G39: 0
B40: 10. b) Value adjustments regarding current assets | C40: =C41-C42 -> 1497.2722 | D40: =$C40/$C$24 -> 3.8724257e-05 | E40: =E41-E42 -> -6619.2965 | F40: =$E40/$E$24 -> -0.00017443171 | G40: =G41-G42 -> 36502.01 | H40: =$G40/$G$24 -> 0.0010547315
B41: b. 1) Expenses | C41: 60289.351 | D41: =$C41/$C$24 -> 0.0015592758 | E41: 8057.2864 | F41: =$E41/$E$24 -> 0.00021232562 | G41: 48636.711 | H41: =$G41/$G$24 -> 0.0014053657
B42: b. 2) Income | C42: 58792.079 | D42: =$C42/$C$24 -> 0.0015205516 | E42: 14676.583 | F42: =$E42/$E$24 -> 0.00038675733 | G42: 12134.7 | H42: =$G42/$G$24 -> 0.00035063414
...

Sheet Balance Sheet 2022-2024 (2)
B2: VioTrans Group SRL | C2: Source: https://www.ecb.europa.eu/stats/policy_and_exchange_rates/euro_reference_exchange_rates/html/eurofxref-graph-ron.de.html
C3: EUR vs. RON | E3: EUR vs. RON | G3: EUR vs. RON
B4: In € | C4: 46021 | E4: 45655 | G4: 45657
C5: 4.949 | E5: 4.975 | G5: 4.974
B7: No. Description | C7: as at December 31, 2022 | E7: as at December 31, 2023 | G7: as at December 31, 2024
B8: NON-CURRENT ASSETS
B9: I. INTANGIBLE ASSETS
B10: 1 Set-up expenses | C10: 0 | E10: 0 | G10: 0
B11: 2 Development expenses | C11: 0 | E11: 0 | G11: 0
B12: 3 Concessions, patents, licenses, trademarks, similar rights and assets and other intangible assets | C12: 4011.3154 | D12: =C12/C37 -> 0.00041856634 | E12: 25585.528 | F12: =E12/E37 -> 0.0034451766 | G12: 19983.514 | H12: =G12/G37 -> 0.0038357813
B13: 4 Goodwill | C13: 0 | E13: 0 | G13: 0
B14: 5 Intangible exploration assets and evaluation of mineral resources | C14: 0 | E14: 0 | G14: 0
B15: 6 Advances | C15: 0 | E15: 0 | G15: 0
B16: TOTAL | C16: =SUM(C10:C15) -> 4011.3154 | D16: =C16/C66 -> 0.00019013009 | E16: =SUM(E10:E15) -> 25585.528 | F16: =E16/E66 -> 0.0013602633 | G16: =SUM(G10:G15) -> 19983.514 | H16: =G16/G66 -> 0.0012980413
B17: II. TANGIBLE ASSETS | C17: 0 | E17: 0 | G17: 0
B18: 1 Land and buildings | C18: 1523198.8 | D18: =$C18/$C$66 -> 0.072197246 | E18: 1452865.5 | F18: =$E18/$E$66 -> 0.077242091 | G18: 1370667.7 | H18: =$G18/$G$66 -> 0.08903255
B19: 2 Installations and machinery | C19: 7850724.8 | D19: =$C19/$C$66 -> 0.37211209 | E19: 5860386.3 | F19: =$E19/$E$66 -> 0.31156944 | G19: 3554068 | H19: =$G19/$G$66 -> 0.23085664
B20: 3 Other installations, machines and furniture | C20: 76867.448 | D20: =$C20/$C$66 -> 0.003643397 | E20: 77261.709 | F20: =$E20/$E$66 -> 0.0041076451 | G20: 154964.82 | H20: =$G20/$G$66 -> 0.010065834
B21: 4 Investment property | C21: 0 | E21: 0 | G21: 0
B22: 5 Tangible assets in progress | C22: 4992.5237 | D22: =$C22/$C$66 -> 0.00023663783 | E22: 0 | G22: 0
B23: 6 Investment property in progress | C23: 0 | E23: 0 | G23: 0
B24: 7 Tangible assets for exploration and valuation of mineral resources | C24: 0 | E24: 0 | G24: 0
B25: 8 Productive biological assets | C25: 0 | E25: 0 | G25: 0
B26: 9 Advances | C26: 120859.57 | D26: =$C26/$C$66 -> 0.0057285547 | E26: 0 | G26: 100002.01 | H26: =$G26/$G$66 -> 0.0064956913
B27: TOTAL | C27: =SUM(C18:C26) -> 9576643.2 | D27: =$C27/$C$66 -> 0.45391793 | E27: =SUM(E18:E26) -> 7390513.6 | F27: =$E27/$E$66 -> 0.39291917 | G27: =SUM(G18:G26) -> 5179702.5 | H27: =$G27/$G$66 -> 0.33645071
B28: III. FINANCIAL ASSETS | C28: 0 | E28: 0 | G28: 0
B29: 1 Investments in related parties | C29: 0 | E29: 0 | G29: 0
B30: 2 Loans granted to related parties | C30: 0 | E30: 0 | G30: 0
B31: 3 Equity investment | C31: 0 | E31: 0 | G31: 0
B32: 4 Loans granted to associated entities and jointly controlled entities | C32: 0 | E32: 0 | G32: 0
B33: 5 Other fixed assets | C33: 0 | E33: 0 | G33: 0
B34: 6 Other loans | C34: 2809.4565 | D34: =$C34/$C$66 -> 0.00013316385 | E34: 10378.693 | F34: =$E34/$E$66 -> 0.00055178678 | G34: 10077.805 | H34: =$G34/$G$66 -> 0.00065460991
B35: TOTAL | C35: =SUM(C29:C34) -> 2809.4565 | D35: =$C35/$C$66 -> 0.00013316385 | E35: =SUM(E29:E34) -> 10378.693 | F35: =$E35/$E$66 -> 0.00055178678 | G35: =SUM(G29:G34) -> 10077.805 | H35: =$G35/$G$66 -> 0.00065460991
B37: TOTAL NON-CURRENT ASSETS | C37: =SUM(C35,C27,C16) -> 9583463.9 | D37: =$C37/$C$66 -> 0.45424122 | E37: =SUM(E35,E27,E16) -> 7426477.8 | F37: =$E37/$E$66 -> 0.39483122 | G37: =SUM(G35,G27,G16) -> 5209763.8 | H37: =$G37/$G$66 -> 0.33840337
B39: CURRENT ASSETS | C39: 0 | E39: 0 | G39: 0
B40: I. INVENTORIES | C40: 0 | E40: 0 | G40: 0
B41: 1 Raw materials and consumables | C41: 144370.78 | D41: =$C41/$C$66 -> 0.0068429496 | E41: 133187.54 | F41: =$E41/$E$66 -> 0.0070809609 | G41: 141271.21 | H41: =$G41/$G$66 -> 0.0091763572
B42: 2 Production in progress | C42: 0 | E42: 0 | G42: 0
B43: 3 Finished goods and commodities | C43: 0 | E43: 0 | G43: 0
B44: 4 Advances | C44: 0 | E44: 0 | G44: 0
...

Sheet Tabelle1
E2: EUR vs. RON | F2: EUR vs. RON
C3: BALANCE SHEET | E3: 45655 | F3: 45657
C4: as at December 31, 2024 | E4: 4.975 | F4: 4.974
C6: No. Description | D6: Row no. | E6: as at December 31, 2023 | F6: as at December 31, 2024
C7: NON-CURRENT ASSETS
C9: I. INTANGIBLE ASSETS
C10: 1 Set-up expenses (acc. 201 - 2801) | D10: 1 | E10: 0 | F10: 0
C11: 2 Development expenses (acc. 2023 - 2803 - 2903) | D11: 2 | E11: 0 | F11: 0
C12: 3 Concessions, patents, licenses, trademarks, similar rights and assets and other intangible assets (acc. 205 + 208 - 2805 - 2808 - 2905 - 2908) | D12: 3 | E12: 127288 | F12: 99398
C13: 4 Goodwill (acc. 2071 - 2807) | D13: 4 | E13: 0 | F13: 0
C14: 5 Intangible exploration assets and evaluation of mineral resources (206 - 2806 - 2906) | D14: 5 | E14: 0 | F14: 0
C15: 6 Advances (acc. 4094 - 4904) | D15: 6 | E15: 0 | F15: 0
C16: TOTAL (row 01 to 06) | D16: 7 | E16: 127288 | F16: 99398
E17: =E16/E4 -> 25585.528 | F17: =F16/F4 -> 19983.514
C18: Test | E18: =E17-'Balance Sheet 2022-2024 (2)'!E16 -> 0 | F18: =F17-'Balance Sheet 2022-2024 (2)'!G16 -> 0
C20: II. TANGIBLE ASSETS
C21: 1 Land and buildings (acc. 211 + 212 - 2811 - 2812 - 2911 - 2912) | D21: 8 | E21: 7228006 | F21: 6817701
C22: 2 Installations and machinery (acc. 213 + 223 - 2813 - 2913) | D22: 9 | E22: 29155422 | F22: 17677934
C23: 3 Other installations, machines and furniture (acc. 214 + 224 - 2814 - 2914) | D23: 10 | E23: 384377 | F23: 770795
C24: 4 Investment property (acc. 215 - 2815 - 2915) | D24: 11 | E24: 0 | F24: 0
C25: 5 Tangible assets in progress (acc. 231 - 2931) | D25: 12 | E25: 0 | F25: 0
C26: 6 Investment property in progress (acc. 235 - 2935) | D26: 13 | E26: 0 | F26: 0
C27: 7 Tangible assets for exploration and valuation of mineral resources (acc. 216 - 2816 - 2916) | D27: 14 | E27: 0 | F27: 0
C28: 8 Productive biological assets (acc. 217 + 227 - 2817 - 2917) | D28: 15 | E28: 0 | F28: 0
C29: 9 Advances (acc. 4093 - 4903) | D29: 16 | E29: 0 | F29: 497410
C30: TOTAL (row 08 to 16) | D30: 17 | E30: 36767805 | F30: 25763840
E31: =E30/E4 -> 7390513.6 | F31: =F30/F4 -> 5179702.5
C32: Test | E32: =E31-'Balance Sheet 2022-2024 (2)'!E27 -> 0 | F32: =F31-'Balance Sheet 2022-2024 (2)'!G27 -> 0
C34: III. FINANCIAL ASSETS
C35: 1 Investments in related parties (acc. 261 - 2961) | D35: 18 | E35: 0 | F35: 0
C36: 2 Loans granted to related parties (acc. 2671 + 2671 - 2964) | D36: 19 | E36: 0 | F36: 0
C37: 3 Equity investment (acc. 262 + 263 - 2962) | D37: 20 | E37: 0 | F37: 0
C38: 4 Loans granted to associated entities and jointly controlled entities (acc. 2673 + 2674 - 2965) | D38: 21 | E38: 0 | F38: 0
C39: 5 Other fixed assets (acc. 265 + 266 - 2963) | D39: 22 | E39: 0 | F39: 0
C40: 6 Other loans (acc. 2675* + 2676* + 2677 + 2678* + 2679* - 2966* - 2968*) | D40: 23 | E40: 51634 | F40: 50127
C41: TOTAL (row 18 to 23) | D41: 24 | E41: 51634 | F41: 50127
E42: =E41/E4 -> 10378.693 | F42: =F41/F4 -> 10077.805
C43: Test | E43: =E42-'Balance Sheet 2022-2024 (2)'!E35 -> 0 | F43: =F42-'Balance Sheet 2022-2024 (2)'!G35 -> 0
C45: TOTAL NON-CURRENT ASSETS (row 07+17+24) | D45: 25 | E45: 36946727 | F45: 25913365
E46: =E45/E4 -> 7426477.8 | F46: =F45/F4 -> 5209763.8
...

Sheet Overview BS
B2: Original Version | L2: Original Translated Version | R2: Steinbeis Version in €
R3: in €
B4: Nr. crt. | C4: Nr. rd. | D4: Mapping | F4: FY23 | H4: sold la 31.09.2024 | J4: FY24 | L4: No. Description | M4: Row no. | N4: FY23 | O4: FY24 | P4: Variation - RON - | R4: No. Description | S4: FY22 | U4: FY23 | W4: FY24
B5: ACTIVE IMOBILIZATE | L5: NON-CURRENT ASSETS | R5: NON-CURRENT ASSETS
B6: I. IMOBILIZĂRI NECORPORALE | L6: I. INTANGIBLE ASSETS | R6: I. INTANGIBLE ASSETS
B7: 1 Cheltuieli de constituire (ct 201 - 2801) | C7: 1 | D7: INTANGIBLES | F7: 0 | H7: 0 | J7: 0 | L7: 1 Set-up expenses (acc. 201 - 2801) | M7: =C7 -> 1 | N7: 0 | O7: 0 | P7: =O7-N7 -> 0 | R7: 1 Set-up expenses | S7: 0 | U7: 0 | W7: 0
B8: 2 Cheltuieli de dezvoltare (ct 203 - 2803 - 2903) | C8: 2 | D8: INTANGIBLES | F8: 0 | H8: 0 | J8: 0 | L8: 2 Development expenses (acc. 2023 - 2803 - 2903) | M8: =C8 -> 2 | N8: =F8 -> 0 | O8: =J8 -> 0 | P8: =O8-N8 -> 0 | R8: 2 Development expenses | S8: 0 | U8: 0 | W8: 0
B9: 3 Concesiuni, brevete, licente, marci comerciale, drepturi si active similare si alte imobilizari necorporale (ct 205 + 208 - 2805 - 2808 - 2905 - 2908) | C9: 3 | D9: INTANGIBLES | F9: 127288 | H9: 0 | J9: 99398 | L9: 3 Concessions, patents, licenses, trademarks, similar rights and assets and other intangible assets (acc. 205 + 208 - 2805 - 2808 - 2905 - 2908) | M9: =C9 -> 3 | N9: =F9 -> 127288 | O9: =J9 -> 99398 | P9: =O9-N9 -> -27890 | R9: 3 Concessions, patents, licenses, trademarks, similar rights and assets and other intangible assets | S9: 4011.3154 | T9: 0.00041856634 | U9: 25585.528 | V9: 0.0034451766 | W9: 19983.514 | X9: 0.0038357813
B10: 4 Fond comercial (ct 2071 - 2807) | C10: 4 | D10: INTANGIBLES | F10: 0 | H10: 0 | J10: 0 | L10: 4 Goodwill (acc. 2071 - 2807) | M10: =C10 -> 4 | N10: =F10 -> 0 | O10: =J10 -> 0 | P10: =O10-N10 -> 0 | R10: 4 Goodwill | S10: 0 | U10: 0 | W10: 0
B11: 5 Active necorporale de explorare si evaluare a resurselor minerale (206 - 2806 - 2906) | C11: 5 | D11: INTANGIBLES | F11: 0 | H11: 0 | J11: 0 | L11: 5 Intangible exploration assets and evaluation of mineral resources (206 - 2806 - 2906) | M11: =C11 -> 5 | N11: =F11 -> 0 | O11: =J11 -> 0 | P11: =O11-N11 -> 0 | R11: 5 Intangible exploration assets and evaluation of mineral resources | S11: 0 | U11: 0 | W11: 0
B12: 6 Avansuri (ct 4094 - 4904) | C12: 6 | D12: INTANGIBLES | F12: 0 | H12: 0 | J12: 0 | L12: 6 Advances (acc. 4094 - 4904) | M12: =C12 -> 6 | N12: =F12 -> 0 | O12: =J12 -> 0 | P12: =O12-N12 -> 0 | R12: 6 Advances | S12: 0 | U12: 0 | W12: 0
B13: TOTAL (rd. 01 la 06) | C13: 7 | F13: 127288 | H13: 0 | J13: 99398 | L13: TOTAL (row 01 to 06) | M13: =C13 -> 7 | N13: =F13 -> 127288 | O13: =J13 -> 99398 | P13: =O13-N13 -> -27890 | R13: TOTAL | S13: 4011.3154 | T13: 0.00019013009 | U13: 25585.528 | V13: 0.0013602633 | W13: 19983.514 | X13: 0.0012980413
B14: II. IMOBILIZĂRI CORPORALE | L14: II. TANGIBLE ASSETS | R14: II. TANGIBLE ASSETS | S14: 0 | U14: 0 | W14: 0
B15: 1 Terenuri si constructii (ct 211 + 212 - 2811 - 2812 - 2911 - 2912) | C15: 8 | D15: PROPERTY | F15: 7228006 | H15: 0 | J15: 6817701 | L15: 1 Land and buildings (acc. 211 + 212 - 2811 - 2812 - 2911 - 2912) | M15: =C15 -> 8 | N15: =F15 -> 7228006 | O15: =J15 -> 6817701 | P15: =O15-N15 -> -410305 | R15: 1 Land and buildings | S15: 1523198.8 | T15: 0.072197246 | U15: 1452865.5 | V15: 0.077242091 | W15: 1370667.7 | X15: 0.08903255
B16: 2 Instalatii tehnice si masini (ct 213 + 223 - 2813 - 2913) | C16: 9 | D16: PROPERTY | F16: 29155422 | H16: 0 | J16: 17677934 | L16: 2 Installations and machinery (acc. 213 + 223 - 2813 - 2913) | M16: =C16 -> 9 | N16: =F16 -> 29155422 | O16: =J16 -> 17677934 | P16: =O16-N16 -> -11477488 | R16: 2 Installations and machinery | S16: 7850724.8 | T16: 0.37211209 | U16: 5860386.3 | V16: 0.31156944 | W16: 3554068 | X16: 0.23085664
B17: 3 Alte instalatii, utilaje si mobilier (ct 214 + 224 - 2814 - 2914) | C17: 10 | D17: PROPERTY | F17: 384377 | H17: 0 | J17: 770795 | L17: 3 Other installations, machines and furniture (acc. 214 + 224 - 2814 - 2914) | M17: =C17 -> 10 | N17: =F17 -> 384377 | O17: =J17 -> 770795 | P17: =O17-N17 -> 386418 | R17: 3 Other installations, machines and furniture | S17: 76867.448 | T17: 0.003643397 | U17: 77261.709 | V17: 0.0041076451 | W17: 154964.82 | X17: 0.010065834
B18: 4 Investitii imobiliare (ct 215 - 2815 - 2915) | C18: 11 | D18: PROPERTY | F18: 0 | H18: 0 | J18: 0 | L18: 4 Investment property (acc. 215 - 2815 - 2915) | M18: =C18 -> 11 | N18: =F18 -> 0 | O18: =J18 -> 0 | P18: =O18-N18 -> 0 | R18: 4 Investment property | S18: 0 | U18: 0 | W18: 0
B19: 5 Imobilizari corporale in curs de executie (ct 231 - 2931) | C19: 12 | D19: PROPERTY | F19: 0 | H19: 0 | J19: 0 | L19: 5 Tangible assets in progress (acc. 231 - 2931) | M19: =C19 -> 12 | N19: =F19 -> 0 | O19: =J19 -> 0 | P19: =O19-N19 -> 0 | R19: 5 Tangible assets in progress | S19: 4992.5237 | T19: 0.00023663783 | U19: 0 | W19: 0
B20: 6 Investitii imobiliare in curs de executie (ct 235 - 2935) | C20: 13 | D20: PROPERTY | F20: 0 | H20: 0 | J20: 0 | L20: 6 Investment property in progress (acc. 235 - 2935) | M20: =C20 -> 13 | N20: =F20 -> 0 | O20: =J20 -> 0 | P20: =O20-N20 -> 0 | R20: 6 Investment property in progress | S20: 0 | U20: 0 | W20: 0
B21: 7 Active corporale de explorare si evaluare a resurselor minerale (ct 216 - 2816 - 2916) | C21: 14 | D21: PROPERTY | F21: 0 | H21: 0 | J21: 0 | L21: 7 Tangible assets for exploration and valuation of mineral resources (acc. 216 - 2816 - 2916) | M21: =C21 -> 14 | N21: =F21 -> 0 | O21: =J21 -> 0 | P21: =O21-N21 -> 0 | R21: 7 Tangible assets for exploration and valuation of mineral resources | S21: 0 | U21: 0 | W21: 0
B22: 8 Active biologice productive (ct 217 + 227 - 2817 - 2917) | C22: 15 | D22: PROPERTY | F22: 0 | H22: 0 | J22: 0 | L22: 8 Productive biological assets (acc. 217 + 227 - 2817 - 2917) | M22: =C22 -> 15 | N22: =F22 -> 0 | O22: =J22 -> 0 | P22: =O22-N22 -> 0 | R22: 8 Productive biological assets | S22: 0 | U22: 0 | W22: 0
B23: 9 Avansuri (ct 4093 - 4903) | C23: 16 | D23: PROPERTY | F23: 0 | H23: 0 | J23: 497410 | L23: 9 Advances (acc. 4093 - 4903) | M23: =C23 -> 16 | N23: =F23 -> 0 | O23: =J23 -> 497410 | P23: =O23-N23 -> 497410 | R23: 9 Advances | S23: 120859.57 | T23: 0.0057285547 | U23: 0 | W23: 100002.01 | X23: 0.0064956913
B24: TOTAL (rd. 08 la 16) | C24: 17 | F24: 36767805 | H24: 0 | J24: 25763840 | L24: TOTAL (row 08 to 16) | M24: =C24 -> 17 | N24: =F24 -> 36767805 | O24: =J24 -> 25763840 | P24: =O24-N24 -> -11003965 | R24: TOTAL | S24: 9576643.2 | T24: 0.45391793 | U24: 7390513.6 | V24: 0.39291917 | W24: 5179702.5 | X24: 0.33645071
B25: III. IMOBILIZĂRI FINANCIARE | L25: III. FINANCIAL ASSETS | R25: III. FINANCIAL ASSETS | S25: 0 | U25: 0 | W25: 0
B26: 1 Actiuni detinute la filiale (ct 261 - 2961) | C26: 18 | D26: FINANCIAL ASSETS | F26: 0 | H26: 0 | J26: 0 | L26: 1 Investments in related parties (acc. 261 - 2961) | M26: =C26 -> 18 | N26: =F26 -> 0 | O26: =J26 -> 0 | P26: =O26-N26 -> 0 | R26: 1 Investments in related parties | S26: 0 | U26: 0 | W26: 0
B27: 2 Imprumuturi acordate entitatilor din grup (ct 2671 + 2672 - 2964) | C27: 19 | D27: FINANCIAL ASSETS | F27: 0 | H27: 0 | J27: 0 | L27: 2 Loans granted to related parties (acc. 2671 + 2671 - 2964) | M27: =C27 -> 19 | N27: =F27 -> 0 | O27: =J27 -> 0 | P27: =O27-N27 -> 0 | R27: 2 Loans granted to related parties | S27: 0 | U27: 0 | W27: 0
B28: 3 Actiunile detinute la entitatile asociate si la entitatile controlate in comun (ct 262 + 263 - 2962) | C28: 20 | D28: FINANCIAL ASSETS | F28: 0 | H28: 0 | J28: 0 | L28: 3 Equity investment (acc. 262 + 263 - 2962) | M28: =C28 -> 20 | N28: =F28 -> 0 | O28: =J28 -> 0 | P28: =O28-N28 -> 0 | R28: 3 Equity investment | S28: 0 | U28: 0 | W28: 0
B29: 4 Imprumuturi acordate entitatilor asociate si entitatilor controlate in comun (ct 2673 + 2674 - 2965) | C29: 21 | D29: FINANCIAL ASSETS | F29: 0 | H29: 0 | J29: 0 | L29: 4 Loans granted to associated entities and jointly controlled entities (acc. 2673 + 2674 - 2965) | M29: =C29 -> 21 | N29: =F29 -> 0 | O29: =J29 -> 0 | P29: =O29-N29 -> 0 | R29: 4 Loans granted to associated entities and jointly controlled entities | S29: 0 | U29: 0 | W29: 0
B30: 5 Alte titluri imobilizate (ct 265 - 2963) | C30: 22 | D30: FINANCIAL ASSETS | F30: 0 | H30: 0 | J30: 0 | L30: 5 Other fixed assets (acc. 265 + 266 - 2963) | M30: =C30 -> 22 | N30: =F30 -> 0 | O30: =J30 -> 0 | P30: =O30-N30 -> 0 | R30: 5 Other fixed assets | S30: 0 | U30: 0 | W30: 0
B31: 6 Alte imprumuturi (ct 2675* + 2676* + 2677 + 2678* + 2679* - 2966* - 2968*) | C31: 23 | D31: FINANCIAL ASSETS | F31: 51634 | H31: 0 | J31: 50127 | L31: 6 Other loans (acc. 2675* + 2676* + 2677 + 2678* + 2679* - 2966* - 2968*) | M31: =C31 -> 23 | N31: =F31 -> 51634 | O31: =J31 -> 50127 | P31: =O31-N31 -> -1507 | R31: 6 Other loans | S31: 2809.4565 | T31: 0.00013316385 | U31: 10378.693 | V31: 0.00055178678 | W31: 10077.805 | X31: 0.00065460991
B32: TOTAL (rd. 18 la 23) | C32: 24 | F32: 51634 | H32: 0 | J32: 50127 | L32: TOTAL (row 18 to 23) | M32: =C32 -> 24 | N32: =F32 -> 51634 | O32: =J32 -> 50127 | P32: =O32-N32 -> -1507 | R32: TOTAL | S32: 2809.4565 | T32: 0.00013316385 | U32: 10378.693 | V32: 0.00055178678 | W32: 10077.805 | X32: 0.00065460991
B33: ACTIVE IMOBILIZATE - TOTAL (rd. 07+17+24) | C33: 25 | F33: 36946727 | H33: 0 | J33: 25913365 | L33: TOTAL NON-CURRENT ASSETS (row 07+17+24) | M33: =C33 -> 25 | N33: =F33 -> 36946727 | O33: =J33 -> 25913365 | P33: =O33-N33 -> -11033362 | R33: TOTAL NON-CURRENT ASSETS | S33: 9583463.9 | T33: 0.45424122 | U33: 7426477.8 | V33: 0.39483122 | W33: 5209763.8 | X33: 0.33840337
B34: ACTIVE CIRCULANTE | L34: CURRENT ASSETS | R34: CURRENT ASSETS | S34: 0 | U34: 0 | W34: 0
B35: I. STOCURI | L35: I. INVENTORIES | R35: I. INVENTORIES | S35: 0 | U35: 0 | W35: 0
B36: 1 Materii prime si materiale consumabile (ct 301 + 302 + 303 +/- 308 +321 + 322 + 323 + 328 + 351 + 358 + 381 +/- 388 - 391 - 392 - 3951 - 3958 - 398) | C36: 26 | D36: INVENTORY | F36: 662608 | H36: 0 | J36: 702683 | L36: 1 Raw materials and consumables (acc. 301 + 302 + 303 +/- 308 +321 + 322 + 323 + 328 + 351 + 358 + 381 +/- 388 - 391 - 392 - 3951 - 3958 - 398) | M36: =C36 -> 26 | N36: =F36 -> 662608 | O36: =J36 -> 702683 | P36: =O36-N36 -> 40075 | R36: 1 Raw materials and consumables | S36: 144370.78 | T36: 0.0068429496 | U36: 133187.54 | V36: 0.0070809609 | W36: 141271.21 | X36: 0.0091763572
B37: 2 Productia in curs de executie (ct 331 + 332 + 341 +/- 348* - 393 - 3941 - 3952) | C37: 27 | D37: INVENTORY | F37: 0 | H37: 0 | J37: 0 | L37: 2 Production in progress (acc. 331 + 332 +341 +/- 348* - 393 - 3941 - 3952) | M37: =C37 -> 27 | N37: =F37 -> 0 | O37: =J37 -> 0 | P37: =O37-N37 -> 0 | R37: 2 Production in progress | S37: 0 | U37: 0 | W37: 0
B38: 3 Produse finite si marfuri (ct 327 + 345 + 346 + 347 +/- 348* + 354 + 356 + 357 + 361 + 326 +/- 368 + 371 +/- 378 - 3945 - 3946 - 3947 - 3953 - 3954 - 3955 - 3956 - 3957 - 396 - 397 - din ct 4428) | C38: 28 | D38: INVENTORY | F38: 0 | H38: 0 | J38: 0 | L38: 3 Finished goods and commodities (acc. 327 + 345 + 346 + 347 +/- 348* + 354 + 356 + 357 + 361 + 326 +/- 368 + 371 +/- 378 - 3945 - 3946 - 3947 - 3953 - 3954 - 3955 - 3956 - 3957 - 396 - 397 - din ct 4428) | M38: =C38 -> 28 | N38: =F38 -> 0 | O38: =J38 -> 0 | P38: =O38-N38 -> 0 | R38: 3 Finished goods and commodities | S38: 0 | U38: 0 | W38: 0
B39: 4 Avansuri (ct 4091 - 4901) | C39: 29 | D39: INVENTORY | F39: 0 | H39: 0 | J39: 0 | L39: 4 Advances (acc. 4091 - 4901) | M39: =C39 -> 29 | N39: =F39 -> 0 | O39: =J39 -> 0 | P39: =O39-N39 -> 0 | R39: 4 Advances | S39: 0 | U39: 0 | W39: 0
B40: TOTAL (rd. 26 la 29) | C40: 30 | F40: 662608 | H40: 0 | J40: 702683 | L40: TOTAL (row 26 to 29) | M40: =C40 -> 30 | N40: =F40 -> 662608 | O40: =J40 -> 702683 | P40: =O40-N40 -> 40075 | R40: TOTAL | S40: 144370.78 | T40: 0.0068429496 | U40: 133187.54 | V40: 0.0070809609 | W40: 141271.21 | X40: 0.0091763572
B41: II. CREANȚE | L41: II. RECEIVABLES | R41: II. RECEIVABLES | S41: 0 | U41: 0 | W41: 0
...

Sheet Overview PL
B2: Original Version | K2: Original Translated Version | Q2: Steinbeis Version in €
B4: Nr. crt. | C4: Nr. rd. | E4: FY 23 | G4: ="perioada incheiata la "&TEXT('[1]SETUP INFO'!F10,"[$-418]d mmmm yyyy;@") -> perioada incheiata la d 00 yyyy | I4: FY 24 | K4: No. Description | L4: Row no. | M4: FY 23 | N4: ="for the period ended "&TEXT('[1]SETUP INFO'!F10,"[$-409]mmmm d, yyyy;@") -> for the period ended 00 d, yyyy | O4: FY 24 | Q4: No. Description | R4: FY22 | T4: FY23 | V4: FY24
B5: 1. Cifra de afaceri neta (rd. 03 + 04 - 05 + 06) | C5: 1 | E5: 186046564 | G5: 0 | I5: 169150363 | K5: 1. Net turnover (row 03 + 04 - 05 + 06) | L5: =C5 -> 1 | M5: =E5 -> 186046564 | N5: =G5 -> 0 | O5: =I5 -> 169150363 | Q5: 1. Net turnover | R5: 38216486 | S5: 0.9884008 | T5: 37396294 | U5: 0.98546718 | V5: 34006909 | W5: 0.98263516
B6: - din care cifra de afaceri neta corespunzatoare activitatii preponderente efectiv desfasurate | C6: =C5+1 -> 2 | E6: 176947139 | I6: 159646280 | K6: - out of which net turnover for the main activity | L6: =C6 -> 2 | M6: =E6 -> 176947139 | N6: =G6 -> 0 | O6: =I6 -> 159646280 | Q6: - out of which net turnover for the main activity | R6: 0 | T6: 0 | V6: 32096156
B7: - din care cifra de afaceri netă realizată din operațiuni desfășurate pe teritoriul național | C7: 2b | E7: 2307555.2 | I7: 1698652.1 | K7: - out of which, the net turnover achieved from operations carried out on national territory | L7: 2b | M7: =E7 -> 2307555.2 | N7: =G7 -> 0 | O7: =I7 -> 1698652.1 | Q7: - out of which, the net turnover achieved from operations carried out on national territory | R7: 0 | T7: 0 | V7: 341506.25
B8: Productia vanduta (ct 701 + 702 + 703 + 704 + 705 + 706 + 708 ) | C8: =C6+1 -> 3 | E8: 177341773 | G8: 0 | I8: 160152300 | K8: Sales of goods (acc. 701 + 702 + 703 + 704 + 705 + 706 + 708) | L8: =C8 -> 3 | M8: =E8 -> 177341773 | N8: =G8 -> 0 | O8: =I8 -> 160152300 | Q8: Sales of goods | R8: 36069540 | S8: 0.93287391 | T8: 0 | U8: 0 | V8: 32197889 | W8: 0.93036324
B9: Venituri din vanzarea marfurilor (ct 707 ) | C9: 4 | E9: 8704791 | G9: 0 | I9: 8998063 | K9: Sales of merchandise (acc. 707) | L9: =C9 -> 4 | M9: =E9 -> 8704791 | N9: =G9 -> 0 | O9: =I9 -> 8998063 | Q9: Sales of merchandise | R9: 2146945.6 | S9: 0.055526895 | T9: 0 | U9: 0 | V9: 1809019.5 | W9: 0.052271913
B10: Reduceri comerciale acordate (ct 709) | C10: 5 | E10: 0 | G10: 0 | I10: 0 | K10: Discounts granted (acc. 709) | L10: =C10 -> 5 | M10: =E10 -> 0 | N10: =G10 -> 0 | O10: =I10 -> 0 | Q10: Discounts granted | R10: 0 | T10: 0 | V10: 0
B11: Venituri din subventii de exploatare aferente cifrei de afaceri nete (ct 7411) | C11: 6 | E11: 0 | G11: 0 | I11: 0 | K11: Revenue from operating subsidies related to the turnover (acc. 7411) | L11: =C11 -> 6 | M11: =E11 -> 0 | N11: =G11 -> 0 | O11: =I11 -> 0 | Q11: Revenue from operating subsidies related to the turnover | R11: 0 | T11: 0 | V11: 0
B12: 2. Venituri aferente costului productiei in curs de executie(ct 711+712) - Sold C | C12: 7 | E12: 0 | G12: 0 | I12: 0 | K12: 2. Revenue related to the cost of the work in progress (acc. 711+712) - Cr Balance | L12: =C12 -> 7 | M12: =E12 -> 0 | N12: =G12 -> 0 | O12: =I12 -> 0 | Q12: 2. Revenue related to the cost of the work in progress | R12: 0 | T12: 0 | V12: 0
B13: Venituri aferente costului productiei in curs de executie(ct 711+712) - Sold D | C13: 8 | E13: 0 | G13: 0 | I13: 0 | K13: Revenue related to the cost of the work in progress (acc. 711 + 712) - Dr Balance | L13: =C13 -> 8 | M13: =E13 -> 0 | N13: =G13 -> 0 | O13: =I13 -> 0 | Q13: Revenue related to the cost of the work in progress | R13: 0 | T13: 0 | V13: 0
B14: 3. Venituri din productia de imobilizari necorporale si corporale (ct 721 + 722) | C14: 9 | E14: 0 | G14: 0 | I14: 0 | K14: 3. Income from production of tangible and intangible assets (acc. 721 + 722) | L14: =C14 -> 9 | M14: =E14 -> 0 | N14: =G14 -> 0 | O14: =I14 -> 0 | Q14: 3. Income from production of tangible and intangible assets | R14: 0 | T14: 0 | V14: 0
B15: 4. Venituri din reevaluarea imobilizarilor corporale (ct 755) | C15: 10 | E15: 0 | G15: 0 | I15: 0 | K15: 4. Income from the revaluation of tangible assets (acc. 755) | L15: =C15 -> 10 | M15: =E15 -> 0 | N15: =G15 -> 0 | O15: =I15 -> 0 | Q15: 4. Income from the revaluation of tangible assets | R15: 0 | T15: 0 | V15: 0
B16: 5. Venituri din productia de investitii imobiliare (ct 725) | C16: 11 | E16: 0 | G16: 0 | I16: 0 | K16: 5. Income from production of real estate investments (acc. 725) | L16: =C16 -> 11 | M16: =E16 -> 0 | N16: =G16 -> 0 | O16: =I16 -> 0 | Q16: 5. Income from production of real estate investments | R16: 0 | T16: 0 | V16: 0
B17: 6. Venituri din subventii de exploatare (ct 7412 + 7413 + 7414 + 7415 +7416 + 7417 + 7419) | C17: 12 | E17: 0 | G17: 0 | I17: 0 | K17: 6. Income from operating subsidies (acc. 7412 + 7413 + 7414 + 7415 + 7416 + 7417 + 7419) | L17: =C17 -> 12 | M17: =E17 -> 0 | N17: =G17 -> 0 | O17: =I17 -> 0 | Q17: 6. Income from operating subsidies | R17: 0 | T17: 0 | V17: 0
B18: 7. Alte venituri din exploatare (ct 751 + 758 + 7815) | C18: 13 | E18: 2743654 | G18: 0 | I18: 2989176 | K18: 7. Other operating income (acc. 751 + 758 + 7815) | L18: =C18 -> 13 | M18: =E18 -> 2743654 | N18: =G18 -> 0 | O18: =I18 -> 2989176 | Q18: 7. Other operating income | R18: 448482.52 | S18: 0.011599195 | T18: 551488.24 | U18: 0.014532819 | V18: 600960.19 | W18: 0.017364843
B19: - din care, venituri din subventii pentru investitii (ct 7584) | C19: 14 | E19: 0 | G19: 0 | I19: 0 | K19: - out of which, income from investment subsidies (acc. 7584) | L19: =C19 -> 14 | M19: =E19 -> 0 | N19: =G19 -> 0 | O19: =I19 -> 0 | Q19: - out of which, income from investment subsidies | R19: 6159.6282 | S19: 0.00015930773 | T19: 0 | V19: 0
B20: - din care, venituri din fondul comercial negativ (ct 7815) | C20: 15 | E20: 0 | G20: 0 | I20: 0 | K20: - out of which, income from negative goodwill (acc. 7815) | L20: =C20 -> 15 | M20: =E20 -> 0 | N20: =G20 -> 0 | O20: =I20 -> 0 | Q20: - out of which, income from negative goodwill | R20: 0 | T20: 0 | V20: 0
B21: VENITURI DIN EXPLOATARE - TOTAL (rd. 01+07-08+09+10+11+12+13) | C21: 16 | E21: 188790218 | G21: 0 | I21: 172139539 | K21: OPERATING INCOME – TOTAL (rows 01 + 07 – 08 + 09 + 10 + 11 + 12 + 13) | L21: =C21 -> 16 | M21: =E21 -> 188790218 | N21: =G21 -> 0 | O21: =I21 -> 172139539 | Q21: OPERATING INCOME – TOTAL | R21: 38664968 | S21: 1.0001593 | T21: 37947783 | U21: 0.014532819 | V21: 34607869 | W21: 1
B22: 8. a) Cheltuieli cu materiile prime si materialele consumabile (ct 601 + 602) | C22: 17 | E22: 32409315 | G22: 0 | I22: 28691875 | K22: 8. a) Expenses related to raw materials and consumables (acc. 601 + 602) | L22: =C22 -> 17 | M22: =E22 -> 32409315 | N22: =G22 -> 0 | O22: =I22 -> 28691875 | Q22: 8. a) Expenses related to raw materials and consumables | R22: 6764286.9 | S22: 0.17494614 | T22: 6514435.2 | U22: 0.1716684 | V22: 5768370.5 | W22: 0.16667801
B23: Alte cheltuieli materiale (ct 603 + 604 + 606 + 608) | C23: 18 | E23: 165212 | G23: 0 | I23: 108982 | K23: Other material expenses (acc. 603 + 604 + 606 + 608) | L23: =C23 -> 18 | M23: =E23 -> 165212 | N23: =G23 -> 0 | O23: =I23 -> 108982 | Q23: Other material expenses | R23: 30171.752 | S23: 0.0007803382 | T23: 33208.442 | U23: 0.0008751089 | V23: 21910.334 | W23: 0.00063310266
B24: b) Alte cheltuieli externe (cu energie si apa) (ct 605) | C24: 19 | E24: 304137 | G24: 0 | I24: 202518 | K24: b) Other external expenses (power and water supply) (acc. 605) | L24: =C24 -> 19 | M24: =E24 -> 304137 | N24: =G24 -> 0 | O24: =I24 -> 202518 | Q24: b) Other external expenses (power and water supply) | R24: 86376.44 | S24: 0.0022339716 | T24: 61133.065 | U24: 0.0016109786 | V24: 40715.32 | W24: 0.0011764758
B25: din care, cheltuieli privind consumul de energie(ct.6051) | C25: 20 | E25: 292980 | G25: 0 | I25: 185075 | K25: - out of which, expenses with power consumption (acc. 6051) | L25: =C25 -> 20 | M25: =E25 -> 292980 | N25: =G25 -> 0 | O25: =I25 -> 185075 | Q25: - out of which, expenses with power consumption | R25: 84990.099 | S25: 0.0021981163 | T25: 58890.452 | U25: 0.0015518813 | V25: 37208.484 | W25: 0.0010751452
B26: din care, cheltuieli privind consumul de gaze naturale(ct.6053) | C26: 21 | E26: 0 | G26: 0 | I26: 0 | K26: - out of which, expenses with natural gas consumption (acc. 6053) | L26: =C26 -> 21 | M26: =E26 -> 0 | N26: =G26 -> 0 | O26: =I26 -> 0 | Q26: - out of which, expenses with natural gas consumption | R26: 0 | T26: 0 | V26: 0
B27: c) Cheltuieli privind marfurile (ct 607) | C27: 22 | E27: 8700332 | G27: 0 | I27: 8997248 | K27: c) Merchandise expenses (acc. 607) | L27: =C27 -> 22 | M27: =E27 -> 8700332 | N27: =G27 -> 0 | O27: =I27 -> 8997248 | Q27: c) Merchandise expenses | R27: 2145422.1 | S27: 0.055487491 | T27: 1748810.5 | U27: 0.046084655 | V27: 1808855.6 | W27: 0.052267178
B28: Reduceri comerciale primite (ct 609) | C28: 23 | E28: 0 | G28: 0 | I28: 0 | K28: Commercial discounts received (acc. 609) | L28: =C28 -> 23 | M28: =E28 -> 0 | N28: =G28 -> 0 | O28: =I28 -> 0 | Q28: Commercial discounts received | R28: 0 | T28: 0 | V28: 0
B29: 9. Cheltuieli cu personalul (rd. 25+26) | C29: 24 | E29: 20738502 | G29: 0 | I29: 21306331 | K29: 9. Personnel expenses (rows 25 + 26), out of which: | L29: =C29 -> 24 | M29: =E29 -> 20738502 | N29: =G29 -> 0 | O29: =I29 -> 21306331 | Q29: 9. Personnel expenses | R29: 3420668.4 | S29: 0.088469448 | T29: 4168543.1 | U29: 0.10984945 | V29: 4283540.6 | W29: 0.1237736
B30: a) Salarii si indemnizatii (ct 641 + 642 + 643 + 644) | C30: 25 | E30: 20293964 | G30: 0 | I30: 20834115 | K30: a) Salaries and allowance (acc. 641 + 642 + 643 + 644) | L30: =C30 -> 25 | M30: =E30 -> 20293964 | N30: =G30 -> 0 | O30: =I30 -> 20834115 | Q30: a) Salaries and allowance | R30: 3347551.6 | S30: 0.086578413 | T30: 4079188.7 | U30: 0.10749479 | V30: 4188603.7 | W30: 0.12103039
B31: b) Cheltuieli cu asigurarile si protectia sociala (ct 645+646) | C31: 26 | E31: 444538 | G31: 0 | I31: 472216 | K31: b) Social security (acc. 645 + 646) | L31: =C31 -> 26 | M31: =E31 -> 444538 | N31: =G31 -> 0 | O31: =I31 -> 472216 | Q31: b) Social security | R31: 73116.791 | S31: 0.0018910346 | T31: 89354.372 | U31: 0.0023546665 | V31: 94936.872 | W31: 0.0027432164
B32: 10. a) Ajustari de valoare privind imobilizarile corporale si necorporale (rd. 28+-29-30) | C32: 27 | E32: 14479166 | G32: 0 | I32: 12445466 | K32: 10. a) Value adjustments regarding tangible and intangible assets (rows 28+29-30) | L32: =C32 -> 27 | M32: =E32 -> 14479166 | N32: =G32 -> 0 | O32: =I32 -> 12445466 | Q32: 10. a) Value adjustments regarding tangible and intangible assets | R32: 2860043.2 | S32: 0.073969884 | T32: 2910385.1 | U32: 0.076694472 | V32: 2502104.1 | W32: 0.072298706
B33: a. 1) Cheltuieli de exploatare privind amortizarea imobilizarilor (ct. 6811) | C33: 28 | E33: 14479166 | G33: 0 | I33: 12445466 | K33: a. 1) Expenses with depreciation and amortisation (acc. 6811) | L33: =C33 -> 28 | M33: =E33 -> 14479166 | N33: =G33 -> 0 | O33: =I33 -> 12445466 | Q33: a. 1) Expenses with depreciation and amortisation | R33: 2860043.2 | S33: 0.073969884 | T33: 2910385.1 | U33: 0.076694472 | V33: 2502104.1 | W33: 0.072298706
B34: a. 2) Alte cheltuieli (ct 6813 + 6817+ din ct 6818) | C34: 29 | E34: 0 | G34: 0 | I34: 0 | K34: a. 2) Other expenses (acc. 6813 + 6817+ from acc. 6818) | L34: =C34 -> 29 | M34: =E34 -> 0 | N34: =G34 -> 0 | O34: =I34 -> 0 | Q34: a. 2) Other expenses | R34: 0 | T34: 0 | V34: 0
B35: a. 3) Venituri (ct 7813+ din ct.7818) | C35: 30 | E35: 0 | G35: 0 | I35: 0 | K35: a. 3) Income (acc. 7813 + from acc. 7818) | L35: =C35 -> 30 | M35: =E35 -> 0 | N35: =G35 -> 0 | O35: =I35 -> 0 | Q35: a. 3) Income | R35: 0 | T35: 0 | V35: 0
B36: b) Ajustari de valoare privind activele circulante (rd. 31-32) | C36: 31 | E36: -32931 | G36: 0 | I36: 181561 | K36: 10. b) Value adjustments regarding current assets (rows 31 – 32) | L36: =C36 -> 31 | M36: =E36 -> -32931 | N36: =G36 -> 0 | O36: =I36 -> 181561 | Q36: 10. b) Value adjustments regarding current assets | R36: 1497.2722 | S36: 3.8724257e-05 | T36: -6619.2965 | U36: -0.00017443171 | V36: 36502.01 | W36: 0.0010547315
B37: b. 1) Cheltuieli (ct 654 + 6814 + din ct.6818) | C37: 32 | E37: 40085 | G37: 0 | I37: 241919 | K37: b. 1) Expenses (acc. 654 + 6814 + from acc. 6818) | L37: =C37 -> 32 | M37: =E37 -> 40085 | N37: =G37 -> 0 | O37: =I37 -> 241919 | Q37: b. 1) Expenses | R37: 60289.351 | S37: 0.0015592758 | T37: 8057.2864 | U37: 0.00021232562 | V37: 48636.711 | W37: 0.0014053657
B38: b. 2) Venituri (ct 754 + 7814+ din ct.7818) | C38: 33 | E38: 73016 | G38: 0 | I38: 60358 | K38: b. 2) Income (acc. 754 + 7814 + from acc. 7818) | L38: =C38 -> 33 | M38: =E38 -> 73016 | N38: =G38 -> 0 | O38: =I38 -> 60358 | Q38: b. 2) Income | R38: 58792.079 | S38: 0.0015205516 | T38: 14676.583 | U38: 0.00038675733 | V38: 12134.7 | W38: 0.00035063414
B39: 11. Alte cheltuieli de exploatare (rd. 35 + 36 + 40 + 42 + 44 + 46 + 47 + 48 + 49 + 50) | C39: 34 | E39: 103349844 | G39: 0 | I39: 97460549 | K39: 11. Other operating expenses (rows 35 + 36 + 40 + 42 + 44 + 46 + 47 + 48 + 49 + 50) | L39: =C39 -> 34 | M39: =E39 -> 103349844 | N39: =G39 -> 0 | O39: =I39 -> 97460549 | Q39: 11. Other operating expenses | R39: 20860357 | S39: 0.53951993 | T39: 20773838 | U39: 0.5474322 | V39: 19593999 | W39: 0.56617178
B40: 11.1. Cheltuieli privind prestatiile externe (ct 611 + 613 + 614 + 615 + 621 + 622 + 623 + 624 + 625 + 626 + 627 + 628) | C40: 35 | E40: 99985334 | G40: 0 | I40: 95276172 | K40: 11.1. External services expenses (acc. 611 + 613 + 614 + 615 + 621 + 622 + 623 + 624 + 625 + 626 + 627 + 628) | L40: =C40 -> 35 | M40: =E40 -> 99985334 | N40: =G40 -> 0 | O40: =I40 -> 95276172 | Q40: 11.1. External services expenses | R40: 20609084 | S40: 0.53301695 | T40: 20097555 | U40: 0.52961078 | V40: 19154840 | W40: 0.55348221
B41: 11.2. Cheltuieli cu redeventele, locatiile de gestiune si chiriile (ct 612) | C41: 36 | E41: 174978 | F41: 0 | G41: 0 | I41: 425184 | K41: 11.2.Expenses with Royalties, management leases and rental (acc. 612) | L41: =C41 -> 36 | M41: =E41 -> 174978 | N41: =G41 -> 0 | O41: =I41 -> 425184 | Q41: 11.2.Expenses with Royalties, management leases and rental | R41: 164.07355 | S41: 4.2434678e-06 | T41: 35171.457 | U41: 0.00092683828 | V41: 85481.303 | W41: 0.0024699962
B42: - cheltuieli cu redevente (ct. 6121) | C42: 37 | E42: 0 | G42: 0 | I42: 0 | K42: - Expenses with Royalties (acc. 6121) | M42: =E42 -> 0 | N42: =G42 -> 0 | O42: =I42 -> 0 | Q42: - Expenses with Royalties | R42: 0 | T42: 0 | V42: 0
...
